<?xml version="1.0" ?>
<robot name="robot_model_export" xmlns:xacro="http://www.ros.org/wiki/xacro">

<xacro:include filename="$(find robot_model_export_description)/urdf/materials.xacro" />
<link name="base_link">
  <inertial>
    <origin xyz="0.01124701395298498 0.0002366333255408849 0.0035132919404299713" rpy="0 0 0"/>
    <mass value="1.4695442239084902"/>
    <inertia ixx="0.006044" iyy="0.006199" izz="0.012165" ixy="-1.6e-05" iyz="1e-06" ixz="9.4e-05"/>
  </inertial>
  <visual>
    <origin xyz="0 0 0" rpy="0 0 0"/>
    <geometry>
      <mesh filename="file://$(find robot_model_export_description)/meshes/base_link.stl" scale="0.001 0.001 0.001"/>
    </geometry>
    <material name="silver"/>
  </visual>
  <collision>
    <origin xyz="0 0 0" rpy="0 0 0"/>
    <geometry>
      <mesh filename="file://$(find robot_model_export_description)/meshes/base_link.stl" scale="0.001 0.001 0.001"/>
    </geometry>
  </collision>
</link>

<link name="Left_Motor_1">
  <inertial>
    <origin xyz="0.00010028588786138021 -0.01867209415313599 -2.0602736909916541e-07" rpy="0 0 0"/>
    <mass value="0.5347120284089587"/>
    <inertia ixx="0.000145" iyy="0.000153" izz="0.000146" ixy="1e-06" iyz="0.0" ixz="0.0"/>
  </inertial>
  <visual>
    <origin xyz="0.060312 -0.09339 -0.02715" rpy="0 0 0"/>
    <geometry>
      <mesh filename="file://$(find robot_model_export_description)/meshes/Left_Motor_1.stl" scale="0.001 0.001 0.001"/>
    </geometry>
    <material name="silver"/>
  </visual>
  <collision>
    <origin xyz="0.060312 -0.09339 -0.02715" rpy="0 0 0"/>
    <geometry>
      <mesh filename="file://$(find robot_model_export_description)/meshes/Left_Motor_1.stl" scale="0.001 0.001 0.001"/>
    </geometry>
  </collision>
</link>

<link name="Left_Wheel_Attachment_1">
  <inertial>
    <origin xyz="1.3665929755879436e-08 -0.005408521171114858 3.942507858563024e-05" rpy="0 0 0"/>
    <mass value="0.006547683530071302"/>
    <inertia ixx="1e-06" iyy="0.0" izz="1e-06" ixy="-0.0" iyz="0.0" ixz="0.0"/>
  </inertial>
  <visual>
    <origin xyz="0.060312 -0.11689 -0.02715" rpy="0 0 0"/>
    <geometry>
      <mesh filename="file://$(find robot_model_export_description)/meshes/Left_Wheel_Attachment_1.stl" scale="0.001 0.001 0.001"/>
    </geometry>
    <material name="silver"/>
  </visual>
  <collision>
    <origin xyz="0.060312 -0.11689 -0.02715" rpy="0 0 0"/>
    <geometry>
      <mesh filename="file://$(find robot_model_export_description)/meshes/Left_Wheel_Attachment_1.stl" scale="0.001 0.001 0.001"/>
    </geometry>
  </collision>
</link>

<link name="Left_Wheel_1">
  <inertial>
    <origin xyz="-6.742943193274037e-05 0.014977294887082299 -3.2803523729064976e-05" rpy="0 0 0"/>
    <mass value="2.7743069866386367"/>
    <inertia ixx="0.002143" iyy="0.003129" izz="0.002138" ixy="4e-06" iyz="2e-06" ixz="3e-06"/>
  </inertial>
  <visual>
    <origin xyz="0.060312 -0.12689 -0.02715" rpy="0 0 0"/>
    <geometry>
      <mesh filename="file://$(find robot_model_export_description)/meshes/Left_Wheel_1.stl" scale="0.001 0.001 0.001"/>
    </geometry>
    <material name="silver"/>
  </visual>
  <collision>
    <origin xyz="0.060312 -0.12689 -0.02715" rpy="0 0 0"/>
    <geometry>
      <cylinder radius="0.095" length="0.010"/>
    </geometry>
  </collision>
</link>

<link name="Right_Motor_Mirror___1__1">
  <inertial>
    <origin xyz="0.0001002858878613247 0.01867139493931458 -2.0602736909569597e-07" rpy="0 0 0"/>
    <mass value="0.5347120284089587"/>
    <inertia ixx="0.000145" iyy="0.000153" izz="0.000146" ixy="-1e-06" iyz="-0.0" ixz="0.0"/>
  </inertial>
  <visual>
    <origin xyz="0.060312 0.09261 -0.02715" rpy="0 0 0"/>
    <geometry>
      <mesh filename="file://$(find robot_model_export_description)/meshes/Right_Motor_Mirror___1__1.stl" scale="0.001 0.001 0.001"/>
    </geometry>
    <material name="silver"/>
  </visual>
  <collision>
    <origin xyz="0.060312 0.09261 -0.02715" rpy="0 0 0"/>
    <geometry>
      <mesh filename="file://$(find robot_model_export_description)/meshes/Right_Motor_Mirror___1__1.stl" scale="0.001 0.001 0.001"/>
    </geometry>
  </collision>
</link>

<link name="Right_Wheel_Attachment_Mirror__1">
  <inertial>
    <origin xyz="1.366592969342939e-08 0.00540782195729346 3.942507858565106e-05" rpy="0 0 0"/>
    <mass value="0.006547683530071294"/>
    <inertia ixx="1e-06" iyy="0.0" izz="1e-06" ixy="0.0" iyz="-0.0" ixz="0.0"/>
  </inertial>
  <visual>
    <origin xyz="0.060312 0.11611 -0.02715" rpy="0 0 0"/>
    <geometry>
      <mesh filename="file://$(find robot_model_export_description)/meshes/Right_Wheel_Attachment_Mirror__1.stl" scale="0.001 0.001 0.001"/>
    </geometry>
    <material name="silver"/>
  </visual>
  <collision>
    <origin xyz="0.060312 0.11611 -0.02715" rpy="0 0 0"/>
    <geometry>
      <mesh filename="file://$(find robot_model_export_description)/meshes/Right_Wheel_Attachment_Mirror__1.stl" scale="0.001 0.001 0.001"/>
    </geometry>
  </collision>
</link>

<link name="Right_Wheel_Mirror__1">
  <inertial>
    <origin xyz="-6.742943193280282e-05 -0.014977994100903697 -3.28035237290511e-05" rpy="0 0 0"/>
    <mass value="2.7743069866386367"/>
    <inertia ixx="0.002143" iyy="0.003129" izz="0.002138" ixy="-4e-06" iyz="-2e-06" ixz="3e-06"/>
  </inertial>
  <visual>
    <origin xyz="0.060312 0.12611 -0.02715" rpy="0 0 0"/>
    <geometry>
      <mesh filename="file://$(find robot_model_export_description)/meshes/Right_Wheel_Mirror__1.stl" scale="0.001 0.001 0.001"/>
    </geometry>
    <material name="silver"/>
  </visual>
  <collision>
    <origin xyz="0.060312 0.12611 -0.02715" rpy="0 0 0"/>
    <geometry>
      <cylinder radius="0.095" length="0.010"/>
    </geometry>
  </collision>
</link>

<joint name="Rigid 16" type="fixed">
  <origin xyz="-0.060312 0.09339 0.02715" rpy="0 0 0"/>
  <parent link="base_link"/>
  <child link="Left_Motor_1"/>
</joint>

<joint name="Revolute 17" type="continuous">
  <origin xyz="0.0 0.0235 0.0" rpy="0 0 0"/>
  <parent link="Left_Motor_1"/>
  <child link="Left_Wheel_Attachment_1"/>
  <axis xyz="0.0 1.0 0.0"/>
</joint>

<joint name="Rigid 18" type="fixed">
  <origin xyz="0.0 0.01 0.0" rpy="0 0 0"/>
  <parent link="Left_Wheel_Attachment_1"/>
  <child link="Left_Wheel_1"/>
</joint>

<joint name="Rigid 20" type="fixed">
  <origin xyz="-0.060312 -0.09261 0.02715" rpy="0 0 0"/>
  <parent link="base_link"/>
  <child link="Right_Motor_Mirror___1__1"/>
</joint>

<joint name="Revolute 21" type="continuous">
  <origin xyz="0.0 -0.0235 0.0" rpy="0 0 0"/>
  <parent link="Right_Motor_Mirror___1__1"/>
  <child link="Right_Wheel_Attachment_Mirror__1"/>
  <axis xyz="-0.0 -1.0 0.0"/>
</joint>

<joint name="Rigid 22" type="fixed">
  <origin xyz="0.0 -0.01 0.0" rpy="0 0 0"/>
  <parent link="Right_Wheel_Attachment_Mirror__1"/>
  <child link="Right_Wheel_Mirror__1"/>
</joint>

</robot>
